Traceback (most recent call last):
  File "C:\Users\91932\miniconda3\envs\mlagentbenchopen\Lib\site-packages\urllib3\connection.py", line 174, in _new_conn
    conn = connection.create_connection(
           ^^^^^^^^^^^^^^^^^^^^^^^^^^^^^
  File "C:\Users\91932\miniconda3\envs\mlagentbenchopen\Lib\site-packages\urllib3\util\connection.py", line 72, in create_connection
    for res in socket.getaddrinfo(host, port, family, socket.SOCK_STREAM):
               ^^^^^^^^^^^^^^^^^^^^^^^^^^^^^^^^^^^^^^^^^^^^^^^^^^^^^^^^^^
  File "C:\Users\91932\miniconda3\envs\mlagentbenchopen\Lib\socket.py", line 962, in getaddrinfo
    for res in _socket.getaddrinfo(host, port, family, type, proto, flags):
               ^^^^^^^^^^^^^^^^^^^^^^^^^^^^^^^^^^^^^^^^^^^^^^^^^^^^^^^^^^^
socket.gaierror: [Errno 11001] getaddrinfo failed

During handling of the above exception, another exception occurred:

Traceback (most recent call last):
  File "C:\Users\91932\miniconda3\envs\mlagentbenchopen\Lib\site-packages\urllib3\connectionpool.py", line 715, in urlopen
    httplib_response = self._make_request(
                       ^^^^^^^^^^^^^^^^^^^
  File "C:\Users\91932\miniconda3\envs\mlagentbenchopen\Lib\site-packages\urllib3\connectionpool.py", line 404, in _make_request
    self._validate_conn(conn)
  File "C:\Users\91932\miniconda3\envs\mlagentbenchopen\Lib\site-packages\urllib3\connectionpool.py", line 1058, in _validate_conn
    conn.connect()
  File "C:\Users\91932\miniconda3\envs\mlagentbenchopen\Lib\site-packages\urllib3\connection.py", line 363, in connect
    self.sock = conn = self._new_conn()
                       ^^^^^^^^^^^^^^^^
  File "C:\Users\91932\miniconda3\envs\mlagentbenchopen\Lib\site-packages\urllib3\connection.py", line 186, in _new_conn
    raise NewConnectionError(
urllib3.exceptions.NewConnectionError: <urllib3.connection.HTTPSConnection object at 0x0000022598195610>: Failed to establish a new connection: [Errno 11001] getaddrinfo failed

During handling of the above exception, another exception occurred:

Traceback (most recent call last):
  File "C:\Users\91932\miniconda3\envs\mlagentbenchopen\Lib\site-packages\requests\adapters.py", line 486, in send
    resp = conn.urlopen(
           ^^^^^^^^^^^^^
  File "C:\Users\91932\miniconda3\envs\mlagentbenchopen\Lib\site-packages\urllib3\connectionpool.py", line 799, in urlopen
    retries = retries.increment(
              ^^^^^^^^^^^^^^^^^^
  File "C:\Users\91932\miniconda3\envs\mlagentbenchopen\Lib\site-packages\urllib3\util\retry.py", line 592, in increment
    raise MaxRetryError(_pool, url, error or ResponseError(cause))
urllib3.exceptions.MaxRetryError: HTTPSConnectionPool(host='api-inference.huggingface.co', port=443): Max retries exceeded with url: /models/codellama/CodeLlama-34b-Instruct-hf (Caused by NewConnectionError('<urllib3.connection.HTTPSConnection object at 0x0000022598195610>: Failed to establish a new connection: [Errno 11001] getaddrinfo failed'))

During handling of the above exception, another exception occurred:

Traceback (most recent call last):
  File "D:\TCSCodify\MLAgentBench-open\MLAgentBench\runner.py", line 31, in run
    final_message = agent.run(env)
                    ^^^^^^^^^^^^^^
  File "D:\TCSCodify\MLAgentBench-open\MLAgentBench\agents\agent_research.py", line 114, in run
    completion = complete_text(prompt, log_file, self.args.llm_name)
                 ^^^^^^^^^^^^^^^^^^^^^^^^^^^^^^^^^^^^^^^^^^^^^^^^^^^
  File "D:\TCSCodify\MLAgentBench-open\MLAgentBench\LLM.py", line 268, in complete_text
    completion = complete_text_codellama(prompt, log_file=log_file, model=model, **kwargs)
                 ^^^^^^^^^^^^^^^^^^^^^^^^^^^^^^^^^^^^^^^^^^^^^^^^^^^^^^^^^^^^^^^^^^^^^^^^^
  File "D:\TCSCodify\MLAgentBench-open\MLAgentBench\LLM.py", line 253, in complete_text_codellama
    completion = codellama_client.text_generation(prompt, max_new_tokens=max_tokens_to_sample, truncate=3000,
                 ^^^^^^^^^^^^^^^^^^^^^^^^^^^^^^^^^^^^^^^^^^^^^^^^^^^^^^^^^^^^^^^^^^^^^^^^^^^^^^^^^^^^^^^^^^^^
  File "C:\Users\91932\miniconda3\envs\mlagentbenchopen\Lib\site-packages\huggingface_hub\inference\_client.py", line 1511, in text_generation
    bytes_output = self.post(json=payload, model=model, task="text-generation", stream=stream)  # type: ignore
                   ^^^^^^^^^^^^^^^^^^^^^^^^^^^^^^^^^^^^^^^^^^^^^^^^^^^^^^^^^^^^^^^^^^^^^^^^^^^
  File "C:\Users\91932\miniconda3\envs\mlagentbenchopen\Lib\site-packages\huggingface_hub\inference\_client.py", line 226, in post
    response = get_session().post(
               ^^^^^^^^^^^^^^^^^^^
  File "C:\Users\91932\miniconda3\envs\mlagentbenchopen\Lib\site-packages\requests\sessions.py", line 637, in post
    return self.request("POST", url, data=data, json=json, **kwargs)
           ^^^^^^^^^^^^^^^^^^^^^^^^^^^^^^^^^^^^^^^^^^^^^^^^^^^^^^^^^
  File "C:\Users\91932\miniconda3\envs\mlagentbenchopen\Lib\site-packages\requests\sessions.py", line 589, in request
    resp = self.send(prep, **send_kwargs)
           ^^^^^^^^^^^^^^^^^^^^^^^^^^^^^^
  File "C:\Users\91932\miniconda3\envs\mlagentbenchopen\Lib\site-packages\requests\sessions.py", line 703, in send
    r = adapter.send(request, **kwargs)
        ^^^^^^^^^^^^^^^^^^^^^^^^^^^^^^^
  File "C:\Users\91932\miniconda3\envs\mlagentbenchopen\Lib\site-packages\huggingface_hub\utils\_http.py", line 67, in send
    return super().send(request, *args, **kwargs)
           ^^^^^^^^^^^^^^^^^^^^^^^^^^^^^^^^^^^^^^
  File "C:\Users\91932\miniconda3\envs\mlagentbenchopen\Lib\site-packages\requests\adapters.py", line 519, in send
    raise ConnectionError(e, request=request)
requests.exceptions.ConnectionError: (MaxRetryError("HTTPSConnectionPool(host='api-inference.huggingface.co', port=443): Max retries exceeded with url: /models/codellama/CodeLlama-34b-Instruct-hf (Caused by NewConnectionError('<urllib3.connection.HTTPSConnection object at 0x0000022598195610>: Failed to establish a new connection: [Errno 11001] getaddrinfo failed'))"), '(Request ID: 4ab855af-45e0-4840-b40d-ad90db2560bf)')
